Workbook

Sheet RawData
A1: Inputs (edit blue cells; other sheets recompute via formula)
A3: Area ratio (fp16 : fp-int) | B3: 10.19
A4: Power ratio (fp16 : fp-int) | B4: 3.37
A6: PREFILL raw cycles
B7: s64 | C7: s128 | D7: s256 | E7: s512 | F7: s1024 | G7: s2048 | H7: s4096 | I7: s8192 | J7: s16384
A8: fp16
A9: fp16 qk | B9: 226 | C9: 778 | D9: 3030 | E9: 11845 | F9: 47509 | G9: 182713 | H9: 730800 | I9: 2850100 | J9: 11400400
A10: fp16 pv | B10: 257 | C10: 782 | D10: 2758 | E10: 10248 | F10: 40024 | G10: 156063 | H10: 730800 | I10: 2850100 | J10: 11400400
A11: fp16 qkv | B11: 33510 | C11: 67020 | D11: 134040 | E11: 268080 | F11: 536160 | G11: 1072320 | H11: 2144640 | I11: 4289280 | J11: 8578560
A12: fp16 out | B12: 11170 | C12: 22340 | D12: 44680 | E12: 89360 | F12: 178720 | G12: 357440 | H12: 714880 | I12: 1429760 | J12: 2859520
A13: fp16 ffn | B13: 91395 | C13: 182790 | D13: 365580 | E13: 731160 | F13: 1462320 | G13: 2924640 | H13: 5849280 | I13: 11698560 | J13: 23397120
A15: fi
A16: fi qk | B16: 61 | C16: 95 | D16: 162 | E16: 562 | F16: 2037 | G16: 8222 | H16: 32888 | I16: 131552 | J16: 499897
A17: fi pv | B17: 59 | C17: 93 | D17: 161 | E17: 409 | F17: 1266 | G17: 4629 | H17: 18512 | I17: 74048 | J17: 318406
A18: fi qkv | B18: 885 | C18: 1770 | D18: 3540 | E18: 7080 | F18: 14160 | G18: 28320 | H18: 56640 | I18: 113280 | J18: 226560
A19: fi out | B19: 295 | C19: 590 | D19: 1180 | E19: 2360 | F19: 4720 | G19: 9440 | H19: 18880 | I19: 37760 | J19: 75520
A20: fi ffn | B20: 2331 | C20: 4662 | D20: 9324 | E20: 18648 | F20: 37296 | G20: 74592 | H20: 149184 | I20: 298368 | J20: 596736
A22: improve
A23: imp qk | B23: 54 | C23: 54 | D23: 56 | E23: 54 | F23: 123 | G23: 395 | H23: 1580 | I23: 6320 | J23: 25280
A24: imp pv | B24: 54 | C24: 55 | D24: 55 | E24: 54 | F24: 123 | G24: 328 | H24: 1312 | I24: 5248 | J24: 20992
A25: imp qkv | B25: 78 | C25: 108 | D25: 216 | E25: 429 | F25: 855 | G25: 1713 | H25: 3525 | I25: 7050 | J25: 14100
A26: imp out | B26: 26 | C26: 36 | D26: 72 | E26: 143 | F26: 285 | G26: 571 | H26: 1175 | I26: 2350 | J26: 4700
A27: imp ffn | B27: 204 | C27: 291 | D27: 576 | E27: 1149 | F27: 2301 | G27: 4680 | H27: 9369 | I27: 18720 | J27: 38400
A30: DECODE raw cycles
B31: s64 | C31: s128 | D31: s256 | E31: s512 | F31: s1024 | G31: s2048 | H31: s4096 | I31: s8192 | J31: s16384
A32: fp16
A33: fp16 qk | B33: 99 | C33: 102 | D33: 166 | E33: 246 | F33: 460 | G33: 852 | H33: 1584 | I33: 3186 | J33: 6225
A34: fp16 pv | B34: 95 | C34: 101 | D34: 132 | E34: 234 | F34: 392 | G34: 715 | H34: 1458 | I34: 3008 | J34: 5701
A35: fp16 qkv | B35: 4668 | C35: 4668 | D35: 4668 | E35: 4668 | F35: 4668 | G35: 4668 | H35: 4668 | I35: 4668 | J35: 4668
A36: fp16 out | B36: 1556 | C36: 1556 | D36: 1556 | E36: 1556 | F36: 1556 | G36: 1556 | H36: 1556 | I36: 1556 | J36: 1556
A37: fp16 ffn | B37: 12406 | C37: 12406 | D37: 12406 | E37: 12406 | F37: 12406 | G37: 12406 | H37: 12406 | I37: 12406 | J37: 12406
A39: fi
A40: fi qk | B40: 58 | C40: 57 | D40: 59 | E40: 59 | F40: 59 | G40: 92 | H40: 156 | I40: 263 | J40: 466
A41: fi pv | B41: 57 | C41: 58 | D41: 58 | E41: 58 | F41: 58 | G41: 92 | H41: 156 | I41: 230 | J41: 432
A42: fi qkv | B42: 126 | C42: 126 | D42: 126 | E42: 126 | F42: 126 | G42: 126 | H42: 126 | I42: 126 | J42: 126
A43: fi out | B43: 42 | C43: 42 | D43: 42 | E43: 42 | F43: 42 | G43: 42 | H43: 42 | I43: 42 | J43: 42
A44: fi ffn | B44: 327 | C44: 327 | D44: 327 | E44: 327 | F44: 327 | G44: 327 | H44: 327 | I44: 327 | J44: 327
A46: improve
A47: imp qk | B47: 54 | C47: 54 | D47: 54 | E47: 54 | F47: 54 | G47: 54 | H47: 55 | I47: 89 | J47: 122
A48: imp pv | B48: 54 | C48: 54 | D48: 54 | E48: 54 | F48: 54 | G48: 54 | H48: 54 | I48: 88 | J48: 88
...

Sheet ISO-AREA
A1: ISO-AREA breakdown (formulas use RawData!$B$3)
A3: Prefill · s512
A4: Component | B4: C1 | C4: C2 | D4: C3 | E4: C4
A5: qk | B5: =RawData!$E$9/RawData!$B$3 -> 1162.4141 | C5: =RawData!$E$9/RawData!$B$3 -> 1162.4141 | D5: =RawData!$E$16 -> 562 | E5: =RawData!$E$23 -> 54
A6: pv | B6: =RawData!$E$10/RawData!$B$3 -> 1005.6919 | C6: =RawData!$E$10/RawData!$B$3 -> 1005.6919 | D6: =RawData!$E$17 -> 409 | E6: =RawData!$E$24 -> 54
A7: qkv | B7: =RawData!$E$11/RawData!$B$3 -> 26308.145 | C7: =RawData!$E$18 -> 7080 | D7: =RawData!$E$18 -> 7080 | E7: =RawData!$E$25 -> 429
A8: out | B8: =RawData!$E$12/RawData!$B$3 -> 8769.3817 | C8: =RawData!$E$19 -> 2360 | D8: =RawData!$E$19 -> 2360 | E8: =RawData!$E$26 -> 143
A9: ffn | B9: =RawData!$E$13/RawData!$B$3 -> 71752.699 | C9: =RawData!$E$20 -> 18648 | D9: =RawData!$E$20 -> 18648 | E9: =RawData!$E$27 -> 1149
A10: TOTAL | B10: =SUM(B5:B9) -> 108998.33 | C10: =SUM(C5:C9) -> 30256.106 | D10: =SUM(D5:D9) -> 29059 | E10: =SUM(E5:E9) -> 1829
A12: Prefill · s16384
A13: Component | B13: C1 | C13: C2 | D13: C3 | E13: C4
A14: qk | B14: =RawData!$J$9/RawData!$B$3 -> 1118783.1 | C14: =RawData!$J$9/RawData!$B$3 -> 1118783.1 | D14: =RawData!$J$16 -> 499897 | E14: =RawData!$J$23 -> 25280
A15: pv | B15: =RawData!$J$10/RawData!$B$3 -> 1118783.1 | C15: =RawData!$J$10/RawData!$B$3 -> 1118783.1 | D15: =RawData!$J$17 -> 318406 | E15: =RawData!$J$24 -> 20992
A16: qkv | B16: =RawData!$J$11/RawData!$B$3 -> 841860.65 | C16: =RawData!$J$18 -> 226560 | D16: =RawData!$J$18 -> 226560 | E16: =RawData!$J$25 -> 14100
A17: out | B17: =RawData!$J$12/RawData!$B$3 -> 280620.22 | C17: =RawData!$J$19 -> 75520 | D17: =RawData!$J$19 -> 75520 | E17: =RawData!$J$26 -> 4700
A18: ffn | B18: =RawData!$J$13/RawData!$B$3 -> 2296086.4 | C18: =RawData!$J$20 -> 596736 | D18: =RawData!$J$20 -> 596736 | E18: =RawData!$J$27 -> 38400
A19: TOTAL | B19: =SUM(B14:B18) -> 5656133.5 | C19: =SUM(C14:C18) -> 3136382.2 | D19: =SUM(D14:D18) -> 1717119 | E19: =SUM(E14:E18) -> 103472
A21: Decode · s512
A22: Component | B22: C1 | C22: C2 | D22: C3 | E22: C4
A23: qk | B23: =RawData!$E$33/RawData!$B$3 -> 24.141315 | C23: =RawData!$E$33/RawData!$B$3 -> 24.141315 | D23: =RawData!$E$40 -> 59 | E23: =RawData!$E$47 -> 54
A24: pv | B24: =RawData!$E$34/RawData!$B$3 -> 22.96369 | C24: =RawData!$E$34/RawData!$B$3 -> 22.96369 | D24: =RawData!$E$41 -> 58 | E24: =RawData!$E$48 -> 54
A25: qkv | B25: =RawData!$E$35/RawData!$B$3 -> 458.09617 | C25: =RawData!$E$42 -> 126 | D25: =RawData!$E$42 -> 126 | E25: =RawData!$E$49 -> 48
A26: out | B26: =RawData!$E$36/RawData!$B$3 -> 152.69872 | C26: =RawData!$E$43 -> 42 | D26: =RawData!$E$43 -> 42 | E26: =RawData!$E$50 -> 16
A27: ffn | B27: =RawData!$E$37/RawData!$B$3 -> 1217.4681 | C27: =RawData!$E$44 -> 327 | D27: =RawData!$E$44 -> 327 | E27: =RawData!$E$51 -> 129
A28: TOTAL | B28: =SUM(B23:B27) -> 1875.368 | C28: =SUM(C23:C27) -> 542.105 | D28: =SUM(D23:D27) -> 612 | E28: =SUM(E23:E27) -> 301
A30: Decode · s16384
A31: Component | B31: C1 | C31: C2 | D31: C3 | E31: C4
A32: qk | B32: =RawData!$J$33/RawData!$B$3 -> 610.89303 | C32: =RawData!$J$33/RawData!$B$3 -> 610.89303 | D32: =RawData!$J$40 -> 466 | E32: =RawData!$J$47 -> 122
A33: pv | B33: =RawData!$J$34/RawData!$B$3 -> 559.47007 | C33: =RawData!$J$34/RawData!$B$3 -> 559.47007 | D33: =RawData!$J$41 -> 432 | E33: =RawData!$J$48 -> 88
A34: qkv | B34: =RawData!$J$35/RawData!$B$3 -> 458.09617 | C34: =RawData!$J$42 -> 126 | D34: =RawData!$J$42 -> 126 | E34: =RawData!$J$49 -> 48
A35: out | B35: =RawData!$J$36/RawData!$B$3 -> 152.69872 | C35: =RawData!$J$43 -> 42 | D35: =RawData!$J$43 -> 42 | E35: =RawData!$J$50 -> 16
A36: ffn | B36: =RawData!$J$37/RawData!$B$3 -> 1217.4681 | C36: =RawData!$J$44 -> 327 | D36: =RawData!$J$44 -> 327 | E36: =RawData!$J$51 -> 129
A37: TOTAL | B37: =SUM(B32:B36) -> 2998.6261 | C37: =SUM(C32:C36) -> 1665.3631 | D37: =SUM(D32:D36) -> 1393 | E37: =SUM(E32:E36) -> 403

Sheet ISO-POWER
A1: ISO-POWER breakdown (formulas use RawData!$B$4)
A3: Prefill · s512
A4: Component | B4: C1 | C4: C2 | D4: C3 | E4: C4
A5: qk | B5: =RawData!$E$9/RawData!$B$4 -> 3514.8368 | C5: =RawData!$E$9/RawData!$B$4 -> 3514.8368 | D5: =RawData!$E$16 -> 562 | E5: =RawData!$E$23 -> 54
A6: pv | B6: =RawData!$E$10/RawData!$B$4 -> 3040.9496 | C6: =RawData!$E$10/RawData!$B$4 -> 3040.9496 | D6: =RawData!$E$17 -> 409 | E6: =RawData!$E$24 -> 54
A7: qkv | B7: =RawData!$E$11/RawData!$B$4 -> 79548.961 | C7: =RawData!$E$18 -> 7080 | D7: =RawData!$E$18 -> 7080 | E7: =RawData!$E$25 -> 429
A8: out | B8: =RawData!$E$12/RawData!$B$4 -> 26516.32 | C8: =RawData!$E$19 -> 2360 | D8: =RawData!$E$19 -> 2360 | E8: =RawData!$E$26 -> 143
A9: ffn | B9: =RawData!$E$13/RawData!$B$4 -> 216961.42 | C9: =RawData!$E$20 -> 18648 | D9: =RawData!$E$20 -> 18648 | E9: =RawData!$E$27 -> 1149
A10: TOTAL | B10: =SUM(B5:B9) -> 329582.49 | C10: =SUM(C5:C9) -> 34643.786 | D10: =SUM(D5:D9) -> 29059 | E10: =SUM(E5:E9) -> 1829
A12: Prefill · s16384
A13: Component | B13: C1 | C13: C2 | D13: C3 | E13: C4
A14: qk | B14: =RawData!$J$9/RawData!$B$4 -> 3382908 | C14: =RawData!$J$9/RawData!$B$4 -> 3382908 | D14: =RawData!$J$16 -> 499897 | E14: =RawData!$J$23 -> 25280
A15: pv | B15: =RawData!$J$10/RawData!$B$4 -> 3382908 | C15: =RawData!$J$10/RawData!$B$4 -> 3382908 | D15: =RawData!$J$17 -> 318406 | E15: =RawData!$J$24 -> 20992
A16: qkv | B16: =RawData!$J$11/RawData!$B$4 -> 2545566.8 | C16: =RawData!$J$18 -> 226560 | D16: =RawData!$J$18 -> 226560 | E16: =RawData!$J$25 -> 14100
A17: out | B17: =RawData!$J$12/RawData!$B$4 -> 848522.26 | C17: =RawData!$J$19 -> 75520 | D17: =RawData!$J$19 -> 75520 | E17: =RawData!$J$26 -> 4700
A18: ffn | B18: =RawData!$J$13/RawData!$B$4 -> 6942765.6 | C18: =RawData!$J$20 -> 596736 | D18: =RawData!$J$20 -> 596736 | E18: =RawData!$J$27 -> 38400
A19: TOTAL | B19: =SUM(B14:B18) -> 17102671 | C19: =SUM(C14:C18) -> 7664632 | D19: =SUM(D14:D18) -> 1717119 | E19: =SUM(E14:E18) -> 103472
A21: Decode · s512
A22: Component | B22: C1 | C22: C2 | D22: C3 | E22: C4
A23: qk | B23: =RawData!$E$33/RawData!$B$4 -> 72.997033 | C23: =RawData!$E$33/RawData!$B$4 -> 72.997033 | D23: =RawData!$E$40 -> 59 | E23: =RawData!$E$47 -> 54
A24: pv | B24: =RawData!$E$34/RawData!$B$4 -> 69.436202 | C24: =RawData!$E$34/RawData!$B$4 -> 69.436202 | D24: =RawData!$E$41 -> 58 | E24: =RawData!$E$48 -> 54
A25: qkv | B25: =RawData!$E$35/RawData!$B$4 -> 1385.1632 | C25: =RawData!$E$42 -> 126 | D25: =RawData!$E$42 -> 126 | E25: =RawData!$E$49 -> 48
A26: out | B26: =RawData!$E$36/RawData!$B$4 -> 461.72107 | C26: =RawData!$E$43 -> 42 | D26: =RawData!$E$43 -> 42 | E26: =RawData!$E$50 -> 16
A27: ffn | B27: =RawData!$E$37/RawData!$B$4 -> 3681.3056 | C27: =RawData!$E$44 -> 327 | D27: =RawData!$E$44 -> 327 | E27: =RawData!$E$51 -> 129
A28: TOTAL | B28: =SUM(B23:B27) -> 5670.6231 | C28: =SUM(C23:C27) -> 637.43323 | D28: =SUM(D23:D27) -> 612 | E28: =SUM(E23:E27) -> 301
A30: Decode · s16384
A31: Component | B31: C1 | C31: C2 | D31: C3 | E31: C4
A32: qk | B32: =RawData!$J$33/RawData!$B$4 -> 1847.181 | C32: =RawData!$J$33/RawData!$B$4 -> 1847.181 | D32: =RawData!$J$40 -> 466 | E32: =RawData!$J$47 -> 122
A33: pv | B33: =RawData!$J$34/RawData!$B$4 -> 1691.6914 | C33: =RawData!$J$34/RawData!$B$4 -> 1691.6914 | D33: =RawData!$J$41 -> 432 | E33: =RawData!$J$48 -> 88
A34: qkv | B34: =RawData!$J$35/RawData!$B$4 -> 1385.1632 | C34: =RawData!$J$42 -> 126 | D34: =RawData!$J$42 -> 126 | E34: =RawData!$J$49 -> 48
A35: out | B35: =RawData!$J$36/RawData!$B$4 -> 461.72107 | C35: =RawData!$J$43 -> 42 | D35: =RawData!$J$43 -> 42 | E35: =RawData!$J$50 -> 16
A36: ffn | B36: =RawData!$J$37/RawData!$B$4 -> 3681.3056 | C36: =RawData!$J$44 -> 327 | D36: =RawData!$J$44 -> 327 | E36: =RawData!$J$51 -> 129
A37: TOTAL | B37: =SUM(B32:B36) -> 9067.0623 | C37: =SUM(C32:C36) -> 4033.8724 | D37: =SUM(D32:D36) -> 1393 | E37: =SUM(E32:E36) -> 403
