Workbook

Sheet RawData
A1: Inputs — edit blue cells; other sheets recompute via formula
A3: Area ratio (fp16 : fp-int) | B3: 10.19
A4: Power ratio (fp16 : fp-int) | B4: 3.37
A5: SIMD divisor (softmax/rest) | B5: 4
A7: PREFILL raw cycles
B8: s64 | C8: s128 | D8: s256 | E8: s512 | F8: s1024 | G8: s2048 | H8: s4096 | I8: s8192 | J8: s16384
A9: fp16 qk | B9: 226 | C9: 778 | D9: 3030 | E9: 11845 | F9: 47509 | G9: 182713 | H9: 730800 | I9: 2850100 | J9: 11400400
A10: fp16 pv | B10: 257 | C10: 782 | D10: 2758 | E10: 10248 | F10: 40024 | G10: 156063 | H10: 730800 | I10: 2850100 | J10: 11400400
A11: fp16 qkv | B11: 33510 | C11: 67020 | D11: 134040 | E11: 268080 | F11: 536160 | G11: 1072320 | H11: 2144640 | I11: 4289280 | J11: 8578560
A12: fp16 out | B12: 11170 | C12: 22340 | D12: 44680 | E12: 89360 | F12: 178720 | G12: 357440 | H12: 714880 | I12: 1429760 | J12: 2859520
A13: fp16 ffn | B13: 91395 | C13: 182790 | D13: 365580 | E13: 731160 | F13: 1462320 | G13: 2924640 | H13: 5849280 | I13: 11698560 | J13: 23397120
A14: fi qk | B14: 61 | C14: 95 | D14: 162 | E14: 562 | F14: 2037 | G14: 8222 | H14: 32888 | I14: 131552 | J14: 499897
A15: fi pv | B15: 59 | C15: 93 | D15: 161 | E15: 409 | F15: 1266 | G15: 4629 | H15: 18512 | I15: 74048 | J15: 318406
A16: fi qkv | B16: 885 | C16: 1770 | D16: 3540 | E16: 7080 | F16: 14160 | G16: 28320 | H16: 56640 | I16: 113280 | J16: 226560
A17: fi out | B17: 295 | C17: 590 | D17: 1180 | E17: 2360 | F17: 4720 | G17: 9440 | H17: 18880 | I17: 37760 | J17: 75520
A18: fi ffn | B18: 2331 | C18: 4662 | D18: 9324 | E18: 18648 | F18: 37296 | G18: 74592 | H18: 149184 | I18: 298368 | J18: 596736
A19: imp qk | B19: 54 | C19: 54 | D19: 56 | E19: 54 | F19: 123 | G19: 395 | H19: 1580 | I19: 6320 | J19: 25280
A20: imp pv | B20: 54 | C20: 55 | D20: 55 | E20: 54 | F20: 123 | G20: 328 | H20: 1312 | I20: 5248 | J20: 20992
... A25: rest | B25: 1881 | C25: 3727 | D25: 7370 | E25: 14759 | F25: 29225 | G25: 57206 | H25: 114062 | I25: 231731 | J25: 461232
A28: DECODE BS=1 attention raw
B29: s64 | C29: s128 | D29: s256 | E29: s512 | F29: s1024 | G29: s2048 | H29: s4096 | I29: s8192 | J29: s16384
A30: fp16 qk | B30: 99 | C30: 102 | D30: 166 | E30: 246 | F30: 460 | G30: 852 | H30: 1584 | I30: 3186 | J30: 6225
A31: fp16 pv | B31: 95 | C31: 101 | D31: 132 | E31: 234 | F31: 392 | G31: 715 | H31: 1458 | I31: 3008 | J31: 5701
A32: fi qk | B32: 58 | C32: 57 | D32: 59 | E32: 59 | F32: 59 | G32: 92 | H32: 156 | I32: 263 | J32: 466
A33: fi pv | B33: 57 | C33: 58 | D33: 58 | E33: 58 | F33: 58 | G33: 92 | H33: 156 | I33: 230 | J33: 432
A34: imp qk | B34: 54 | C34: 54 | D34: 54 | E34: 54 | F34: 54 | G34: 54 | H34: 55 | I34: 89 | J34: 122
A35: imp pv | B35: 54 | C35: 54 | D35: 54 | E35: 54 | F35: 54 | G35: 54 | H35: 54 | I35: 88 | J35: 88
A37: DECODE BS=8 attention raw
B38: s64 | C38: s128 | D38: s256 | E38: s512 | F38: s1024 | G38: s2048 | H38: s4096 | I38: s8192 | J38: s16384
A39: fp16 qk | B39: 792 | C39: 816 | D39: 1328 | E39: 1968 | F39: 3680 | G39: 6816 | H39: 12672 | I39: 25488 | J39: 49800
A40: fp16 pv | B40: 760 | C40: 808 | D40: 1056 | E40: 1872 | F40: 3136 | G40: 5720 | H40: 11664 | I40: 24064 | J40: 45608
A41: fi qk | B41: 464 | C41: 456 | D41: 472 | E41: 472 | F41: 472 | G41: 736 | H41: 1248 | I41: 2104 | J41: 3728
A42: fi pv | B42: 456 | C42: 464 | D42: 464 | E42: 464 | F42: 464 | G42: 736 | H42: 1248 | I42: 1840 | J42: 3456
A43: imp qk | B43: 445 | C43: 452 | D43: 457 | E43: 476 | F43: 473 | G43: 480 | H43: 476 | I43: 756 | J43: 1028
A44: imp pv | B44: 444 | C44: 446 | D44: 457 | E44: 480 | F44: 472 | G44: 478 | H44: 481 | I44: 750 | J44: 735
A46: DECODE BS=64 attention raw
B47: s64 | C47: s128 | D47: s256 | E47: s512 | F47: s1024 | G47: s2048 | H47: s4096 | I47: s8192 | J47: s16384
A48: fp16 qk | B48: 6336 | C48: 6528 | D48: 10624 | E48: 15744 | F48: 29440 | G48: 54528 | H48: 101376 | I48: 203904 | J48: 398400
A49: fp16 pv | B49: 6080 | C49: 6464 | D49: 8448 | E49: 14976 | F49: 25088 | G49: 45760 | H49: 93312 | I49: 192512 | J49: 364864
A50: fi qk | B50: 3712 | C50: 3648 | D50: 3776 | E50: 3776 | F50: 3776 | G50: 5888 | H50: 9984 | I50: 16832 | J50: 29824
...

Sheet Prefill
A1: Prefill — totals and speedup vs C1 (formulas)
A3: seq | B3: C1 (ISO-AREA) | C3: C2 (ISO-AREA) | D3: C3 (ISO-AREA) | E3: C4 (ISO-AREA) | F3: C1 (ISO-POWER) | G3: C2 (ISO-POWER) | H3: C3 (ISO-POWER) | I3: C4 (ISO-POWER) | J3: C1 speedup (IA) | K3: C2 speedup (IA) | L3: C3 speedup (IA) | M3: C4 speedup (IA) | N3: C1 speedup (IP) | O3: C2 speedup (IP) | P3: C3 speedup (IP) | Q3: C4 speedup (IP)
A4: s512 | B4: =RawData!$E$9/RawData!$B$3+RawData!$E$10/RawData!$B$3+RawData!$E$11/RawData!$B$3+RawData!$E$12/RawData!$B$3+RawData!$E$13/RawData!$B$3+(RawData!$E$24+RawData!$E$25)/RawData!$B$5 -> 114326.33 | C4: =RawData!$E$9/RawData!$B$3+RawData!$E$10/RawData!$B$3+RawData!$E$16+RawData!$E$17+RawData!$E$18+(RawData!$E$24+RawData!$E$25)/RawData!$B$5 -> 35584.106 | D4: =RawData!$E$14+RawData!$E$15+RawData!$E$16+RawData!$E$17+RawData!$E$18+(RawData!$E$24+RawData!$E$25)/RawData!$B$5 -> 34387 | E4: =RawData!$E$19+RawData!$E$20+RawData!$E$21+RawData!$E$22+RawData!$E$23+(RawData!$E$24+RawData!$E$25)/RawData!$B$5 -> 7157 | F4: =RawData!$E$9/RawData!$B$4+RawData!$E$10/RawData!$B$4+RawData!$E$11/RawData!$B$4+RawData!$E$12/RawData!$B$4+RawData!$E$13/RawData!$B$4+(RawData!$E$24+RawData!$E$25)/RawData!$B$5 -> 334910.49 | G4: =RawData!$E$9/RawData!$B$4+RawData!$E$10/RawData!$B$4+RawData!$E$16+RawData!$E$17+RawData!$E$18+(RawData!$E$24+RawData!$E$25)/RawData!$B$5 -> 39971.786 | H4: =RawData!$E$14+RawData!$E$15+RawData!$E$16+RawData!$E$17+RawData!$E$18+(RawData!$E$24+RawData!$E$25)/RawData!$B$5 -> 34387 | I4: =RawData!$E$19+RawData!$E$20+RawData!$E$21+RawData!$E$22+RawData!$E$23+(RawData!$E$24+RawData!$E$25)/RawData!$B$5 -> 7157 | J4: =B4/B4 -> 1 | K4: =B4/C4 -> 3.2128482 | L4: =B4/D4 -> 3.3246963 | M4: =B4/E4 -> 15.974058 | N4: =F4/F4 -> 1 | O4: =F4/G4 -> 8.3786721 | P4: =F4/H4 -> 9.7394507 | Q4: =F4/I4 -> 46.794815
A5: s1024 | B5: =RawData!$F$9/RawData!$B$3+RawData!$F$10/RawData!$B$3+RawData!$F$11/RawData!$B$3+RawData!$F$12/RawData!$B$3+RawData!$F$13/RawData!$B$3+(RawData!$F$24+RawData!$F$25)/RawData!$B$5 -> 235091.04 | C5: =RawData!$F$9/RawData!$B$3+RawData!$F$10/RawData!$B$3+RawData!$F$16+RawData!$F$17+RawData!$F$18+(RawData!$F$24+RawData!$F$25)/RawData!$B$5 -> 77606.588 | D5: =RawData!$F$14+RawData!$F$15+RawData!$F$16+RawData!$F$17+RawData!$F$18+(RawData!$F$24+RawData!$F$25)/RawData!$B$5 -> 72319.5 | E5: =RawData!$F$19+RawData!$F$20+RawData!$F$21+RawData!$F$22+RawData!$F$23+(RawData!$F$24+RawData!$F$25)/RawData!$B$5 -> 16527.5 | F5: =RawData!$F$9/RawData!$B$4+RawData!$F$10/RawData!$B$4+RawData!$F$11/RawData!$B$4+RawData!$F$12/RawData!$B$4+RawData!$F$13/RawData!$B$4+(RawData!$F$24+RawData!$F$25)/RawData!$B$5 -> 684868.1 | G5: =RawData!$F$9/RawData!$B$4+RawData!$F$10/RawData!$B$4+RawData!$F$16+RawData!$F$17+RawData!$F$18+(RawData!$F$24+RawData!$F$25)/RawData!$B$5 -> 94990.684 | H5: =RawData!$F$14+RawData!$F$15+RawData!$F$16+RawData!$F$17+RawData!$F$18+(RawData!$F$24+RawData!$F$25)/RawData!$B$5 -> 72319.5 | I5: =RawData!$F$19+RawData!$F$20+RawData!$F$21+RawData!$F$22+RawData!$F$23+(RawData!$F$24+RawData!$F$25)/RawData!$B$5 -> 16527.5 | J5: =B5/B5 -> 1 | K5: =B5/C5 -> 3.0292665 | L5: =B5/D5 -> 3.2507282 | M5: =B5/E5 -> 14.224235 | N5: =F5/F5 -> 1 | O5: =F5/G5 -> 7.2098449 | P5: =F5/H5 -> 9.4700336 | Q5: =F5/I5 -> 41.438094
A6: s2048 | B6: =RawData!$G$9/RawData!$B$3+RawData!$G$10/RawData!$B$3+RawData!$G$11/RawData!$B$3+RawData!$G$12/RawData!$B$3+RawData!$G$13/RawData!$B$3+(RawData!$G$24+RawData!$G$25)/RawData!$B$5 -> 494985.08 | C6: =RawData!$G$9/RawData!$B$3+RawData!$G$10/RawData!$B$3+RawData!$G$16+RawData!$G$17+RawData!$G$18+(RawData!$G$24+RawData!$G$25)/RawData!$B$5 -> 180016.18 | D6: =RawData!$G$14+RawData!$G$15+RawData!$G$16+RawData!$G$17+RawData!$G$18+(RawData!$G$24+RawData!$G$25)/RawData!$B$5 -> 159621.25 | E6: =RawData!$G$19+RawData!$G$20+RawData!$G$21+RawData!$G$22+RawData!$G$23+(RawData!$G$24+RawData!$G$25)/RawData!$B$5 -> 42105.25 | F6: =RawData!$G$9/RawData!$B$4+RawData!$G$10/RawData!$B$4+RawData!$G$11/RawData!$B$4+RawData!$G$12/RawData!$B$4+RawData!$G$13/RawData!$B$4+(RawData!$G$24+RawData!$G$25)/RawData!$B$5 -> 1427052.1 | G6: =RawData!$G$9/RawData!$B$4+RawData!$G$10/RawData!$B$4+RawData!$G$16+RawData!$G$17+RawData!$G$18+(RawData!$G$24+RawData!$G$25)/RawData!$B$5 -> 247297.25 | H6: =RawData!$G$14+RawData!$G$15+RawData!$G$16+RawData!$G$17+RawData!$G$18+(RawData!$G$24+RawData!$G$25)/RawData!$B$5 -> 159621.25 | I6: =RawData!$G$19+RawData!$G$20+RawData!$G$21+RawData!$G$22+RawData!$G$23+(RawData!$G$24+RawData!$G$25)/RawData!$B$5 -> 42105.25 | J6: =B6/B6 -> 1 | K6: =B6/C6 -> 2.74967 | L6: =B6/D6 -> 3.1009974 | M6: =B6/E6 -> 11.755899 | N6: =F6/F6 -> 1 | O6: =F6/G6 -> 5.7705941 | P6: =F6/H6 -> 8.9402387 | Q6: =F6/I6 -> 33.892497
A7: s4096 | B7: =RawData!$H$9/RawData!$B$3+RawData!$H$10/RawData!$B$3+RawData!$H$11/RawData!$B$3+RawData!$H$12/RawData!$B$3+RawData!$H$13/RawData!$B$3+(RawData!$H$24+RawData!$H$25)/RawData!$B$5 -> 1102878.8 | C7: =RawData!$H$9/RawData!$B$3+RawData!$H$10/RawData!$B$3+RawData!$H$16+RawData!$H$17+RawData!$H$18+(RawData!$H$24+RawData!$H$25)/RawData!$B$5 -> 472940.99 | D7: =RawData!$H$14+RawData!$H$15+RawData!$H$16+RawData!$H$17+RawData!$H$18+(RawData!$H$24+RawData!$H$25)/RawData!$B$5 -> 380906.25 | E7: =RawData!$H$19+RawData!$H$20+RawData!$H$21+RawData!$H$22+RawData!$H$23+(RawData!$H$24+RawData!$H$25)/RawData!$B$5 -> 121763.25 | F7: =RawData!$H$9/RawData!$B$4+RawData!$H$10/RawData!$B$4+RawData!$H$11/RawData!$B$4+RawData!$H$12/RawData!$B$4+RawData!$H$13/RawData!$B$4+(RawData!$H$24+RawData!$H$25)/RawData!$B$5 -> 3122725.1 | G7: =RawData!$H$9/RawData!$B$4+RawData!$H$10/RawData!$B$4+RawData!$H$16+RawData!$H$17+RawData!$H$18+(RawData!$H$24+RawData!$H$25)/RawData!$B$5 -> 763215.45 | H7: =RawData!$H$14+RawData!$H$15+RawData!$H$16+RawData!$H$17+RawData!$H$18+(RawData!$H$24+RawData!$H$25)/RawData!$B$5 -> 380906.25 | I7: =RawData!$H$19+RawData!$H$20+RawData!$H$21+RawData!$H$22+RawData!$H$23+(RawData!$H$24+RawData!$H$25)/RawData!$B$5 -> 121763.25 | J7: =B7/B7 -> 1 | K7: =B7/C7 -> 2.3319586 | L7: =B7/D7 -> 2.8954075 | M7: =B7/E7 -> 9.057567 | N7: =F7/F7 -> 1 | O7: =F7/G7 -> 4.0915381 | P7: =F7/H7 -> 8.1981461 | Q7: =F7/I7 -> 25.645875
A8: s8192 | B8: =RawData!$I$9/RawData!$B$3+RawData!$I$10/RawData!$B$3+RawData!$I$11/RawData!$B$3+RawData!$I$12/RawData!$B$3+RawData!$I$13/RawData!$B$3+(RawData!$I$24+RawData!$I$25)/RawData!$B$5 -> 2623363.2 | C8: =RawData!$I$9/RawData!$B$3+RawData!$I$10/RawData!$B$3+RawData!$I$16+RawData!$I$17+RawData!$I$18+(RawData!$I$24+RawData!$I$25)/RawData!$B$5 -> 1363487.6 | D8: =RawData!$I$14+RawData!$I$15+RawData!$I$16+RawData!$I$17+RawData!$I$18+(RawData!$I$24+RawData!$I$25)/RawData!$B$5 -> 1009696 | E8: =RawData!$I$19+RawData!$I$20+RawData!$I$21+RawData!$I$22+RawData!$I$23+(RawData!$I$24+RawData!$I$25)/RawData!$B$5 -> 394376 | F8: =RawData!$I$9/RawData!$B$4+RawData!$I$10/RawData!$B$4+RawData!$I$11/RawData!$B$4+RawData!$I$12/RawData!$B$4+RawData!$I$13/RawData!$B$4+(RawData!$I$24+RawData!$I$25)/RawData!$B$5 -> 7214569.3 | G8: =RawData!$I$9/RawData!$B$4+RawData!$I$10/RawData!$B$4+RawData!$I$16+RawData!$I$17+RawData!$I$18+(RawData!$I$24+RawData!$I$25)/RawData!$B$5 -> 2495550 | H8: =RawData!$I$14+RawData!$I$15+RawData!$I$16+RawData!$I$17+RawData!$I$18+(RawData!$I$24+RawData!$I$25)/RawData!$B$5 -> 1009696 | I8: =RawData!$I$19+RawData!$I$20+RawData!$I$21+RawData!$I$22+RawData!$I$23+(RawData!$I$24+RawData!$I$25)/RawData!$B$5 -> 394376 | J8: =B8/B8 -> 1 | K8: =B8/C8 -> 1.9240096 | L8: =B8/D8 -> 2.5981713 | M8: =B8/E8 -> 6.6519341 | N8: =F8/F8 -> 1 | O8: =F8/G8 -> 2.8909736 | P8: =F8/H8 -> 7.1452886 | Q8: =F8/I8 -> 18.293632
A9: s16384 | B9: =RawData!$J$9/RawData!$B$3+RawData!$J$10/RawData!$B$3+RawData!$J$11/RawData!$B$3+RawData!$J$12/RawData!$B$3+RawData!$J$13/RawData!$B$3+(RawData!$J$24+RawData!$J$25)/RawData!$B$5 -> 6928775.5 | C9: =RawData!$J$9/RawData!$B$3+RawData!$J$10/RawData!$B$3+RawData!$J$16+RawData!$J$17+RawData!$J$18+(RawData!$J$24+RawData!$J$25)/RawData!$B$5 -> 4409024.2 | D9: =RawData!$J$14+RawData!$J$15+RawData!$J$16+RawData!$J$17+RawData!$J$18+(RawData!$J$24+RawData!$J$25)/RawData!$B$5 -> 2989761 | E9: =RawData!$J$19+RawData!$J$20+RawData!$J$21+RawData!$J$22+RawData!$J$23+(RawData!$J$24+RawData!$J$25)/RawData!$B$5 -> 1376114 | F9: =RawData!$J$9/RawData!$B$4+RawData!$J$10/RawData!$B$4+RawData!$J$11/RawData!$B$4+RawData!$J$12/RawData!$B$4+RawData!$J$13/RawData!$B$4+(RawData!$J$24+RawData!$J$25)/RawData!$B$5 -> 18375313 | G9: =RawData!$J$9/RawData!$B$4+RawData!$J$10/RawData!$B$4+RawData!$J$16+RawData!$J$17+RawData!$J$18+(RawData!$J$24+RawData!$J$25)/RawData!$B$5 -> 8937274 | H9: =RawData!$J$14+RawData!$J$15+RawData!$J$16+RawData!$J$17+RawData!$J$18+(RawData!$J$24+RawData!$J$25)/RawData!$B$5 -> 2989761 | I9: =RawData!$J$19+RawData!$J$20+RawData!$J$21+RawData!$J$22+RawData!$J$23+(RawData!$J$24+RawData!$J$25)/RawData!$B$5 -> 1376114 | J9: =B9/B9 -> 1 | K9: =B9/C9 -> 1.5714986 | L9: =B9/D9 -> 2.3175015 | M9: =B9/E9 -> 5.0350301 | N9: =F9/F9 -> 1 | O9: =F9/G9 -> 2.056031 | P9: =F9/H9 -> 6.1460808 | Q9: =F9/I9 -> 13.353045

Sheet Decode_BS1
A1: Decode BS=1 — totals and speedup vs C1 (formulas)
A3: seq | B3: C1 (ISO-AREA) | C3: C2 (ISO-AREA) | D3: C3 (ISO-AREA) | E3: C4 (ISO-AREA) | F3: C1 (ISO-POWER) | G3: C2 (ISO-POWER) | H3: C3 (ISO-POWER) | I3: C4 (ISO-POWER) | J3: C1 speedup (IA) | K3: C2 speedup (IA) | L3: C3 speedup (IA) | M3: C4 speedup (IA) | N3: C1 speedup (IP) | O3: C2 speedup (IP) | P3: C3 speedup (IP) | Q3: C4 speedup (IP)
A4: s512 | B4: =(RawData!$E$30+RawData!$E$31+(RawData!$C$57+RawData!$D$57+RawData!$E$57))/RawData!$B$3+(RawData!$E$69+RawData!$E$70)*1/RawData!$B$5 -> 1888.918 | C4: =(RawData!$E$30+RawData!$E$31)/RawData!$B$3+(RawData!$C$60+RawData!$D$60+RawData!$E$60)+(RawData!$E$69+RawData!$E$70)*1/RawData!$B$5 -> 555.655 | D4: =RawData!$E$32+RawData!$E$33+(RawData!$C$60+RawData!$D$60+RawData!$E$60)+(RawData!$E$69+RawData!$E$70)*1/RawData!$B$5 -> 625.55 | E4: =RawData!$E$34+RawData!$E$35+(RawData!$C$63+RawData!$D$63+RawData!$E$63)+(RawData!$E$69+RawData!$E$70)*1/RawData!$B$5 -> 314.55 | F4: =(RawData!$E$30+RawData!$E$31+(RawData!$C$57+RawData!$D$57+RawData!$E$57))/RawData!$B$4+(RawData!$E$69+RawData!$E$70)*1/RawData!$B$5 -> 5684.1731 | G4: =(RawData!$E$30+RawData!$E$31)/RawData!$B$4+(RawData!$C$60+RawData!$D$60+RawData!$E$60)+(RawData!$E$69+RawData!$E$70)*1/RawData!$B$5 -> 650.98323 | H4: =RawData!$E$32+RawData!$E$33+(RawData!$C$60+RawData!$D$60+RawData!$E$60)+(RawData!$E$69+RawData!$E$70)*1/RawData!$B$5 -> 625.55 | I4: =RawData!$E$34+RawData!$E$35+(RawData!$C$63+RawData!$D$63+RawData!$E$63)+(RawData!$E$69+RawData!$E$70)*1/RawData!$B$5 -> 314.55 | J4: =B4/B4 -> 1 | K4: =B4/C4 -> 3.3994439 | L4: =B4/D4 -> 3.0196116 | M4: =B4/E4 -> 6.0051439 | N4: =F4/F4 -> 1 | O4: =F4/G4 -> 8.7316736 | P4: =F4/H4 -> 9.0866808 | Q4: =F4/I4 -> 18.07081
A5: s1024 | B5: =(RawData!$F$30+RawData!$F$31+(RawData!$C$57+RawData!$D$57+RawData!$E$57))/RawData!$B$3+(RawData!$F$69+RawData!$F$70)*1/RawData!$B$5 -> 1927.4244 | C5: =(RawData!$F$30+RawData!$F$31)/RawData!$B$3+(RawData!$C$60+RawData!$D$60+RawData!$E$60)+(RawData!$F$69+RawData!$F$70)*1/RawData!$B$5 -> 594.16138 | D5: =RawData!$F$32+RawData!$F$33+(RawData!$C$60+RawData!$D$60+RawData!$E$60)+(RawData!$F$69+RawData!$F$70)*1/RawData!$B$5 -> 627.55 | E5: =RawData!$F$34+RawData!$F$35+(RawData!$C$63+RawData!$D$63+RawData!$E$63)+(RawData!$F$69+RawData!$F$70)*1/RawData!$B$5 -> 316.55 | F5: =(RawData!$F$30+RawData!$F$31+(RawData!$C$57+RawData!$D$57+RawData!$E$57))/RawData!$B$4+(RawData!$F$69+RawData!$F$70)*1/RawData!$B$5 -> 5796.5589 | G5: =(RawData!$F$30+RawData!$F$31)/RawData!$B$4+(RawData!$C$60+RawData!$D$60+RawData!$E$60)+(RawData!$F$69+RawData!$F$70)*1/RawData!$B$5 -> 763.36899 | H5: =RawData!$F$32+RawData!$F$33+(RawData!$C$60+RawData!$D$60+RawData!$E$60)+(RawData!$F$69+RawData!$F$70)*1/RawData!$B$5 -> 627.55 | I5: =RawData!$F$34+RawData!$F$35+(RawData!$C$63+RawData!$D$63+RawData!$E$63)+(RawData!$F$69+RawData!$F$70)*1/RawData!$B$5 -> 316.55 | J5: =B5/B5 -> 1 | K5: =B5/C5 -> 3.2439409 | L5: =B5/D5 -> 3.0713479 | M5: =B5/E5 -> 6.0888466 | N5: =F5/F5 -> 1 | O5: =F5/G5 -> 7.5933906 | P5: =F5/H5 -> 9.2368081 | Q5: =F5/I5 -> 18.311669
A6: s2048 | B6: =(RawData!$G$30+RawData!$G$31+(RawData!$C$57+RawData!$D$57+RawData!$E$57))/RawData!$B$3+(RawData!$G$69+RawData!$G$70)*1/RawData!$B$5 -> 2002.3412 | C6: =(RawData!$G$30+RawData!$G$31)/RawData!$B$3+(RawData!$C$60+RawData!$D$60+RawData!$E$60)+(RawData!$G$69+RawData!$G$70)*1/RawData!$B$5 -> 669.07821 | D6: =RawData!$G$32+RawData!$G$33+(RawData!$C$60+RawData!$D$60+RawData!$E$60)+(RawData!$G$69+RawData!$G$70)*1/RawData!$B$5 -> 699.3 | E6: =RawData!$G$34+RawData!$G$35+(RawData!$C$63+RawData!$D$63+RawData!$E$63)+(RawData!$G$69+RawData!$G$70)*1/RawData!$B$5 -> 321.3 | F6: =(RawData!$G$30+RawData!$G$31+(RawData!$C$57+RawData!$D$57+RawData!$E$57))/RawData!$B$4+(RawData!$G$69+RawData!$G$70)*1/RawData!$B$5 -> 6013.4751 | G6: =(RawData!$G$30+RawData!$G$31)/RawData!$B$4+(RawData!$C$60+RawData!$D$60+RawData!$E$60)+(RawData!$G$69+RawData!$G$70)*1/RawData!$B$5 -> 980.28516 | H6: =RawData!$G$32+RawData!$G$33+(RawData!$C$60+RawData!$D$60+RawData!$E$60)+(RawData!$G$69+RawData!$G$70)*1/RawData!$B$5 -> 699.3 | I6: =RawData!$G$34+RawData!$G$35+(RawData!$C$63+RawData!$D$63+RawData!$E$63)+(RawData!$G$69+RawData!$G$70)*1/RawData!$B$5 -> 321.3 | J6: =B6/B6 -> 1 | K6: =B6/C6 -> 2.9926863 | L6: =B6/D6 -> 2.8633508 | M6: =B6/E6 -> 6.2319988 | N6: =F6/F6 -> 1 | O6: =F6/G6 -> 6.134414 | P6: =F6/H6 -> 8.599278 | Q6: =F6/I6 -> 18.716076
A7: s4096 | B7: =(RawData!$H$30+RawData!$H$31+(RawData!$C$57+RawData!$D$57+RawData!$E$57))/RawData!$B$3+(RawData!$H$69+RawData!$H$70)*1/RawData!$B$5 -> 2155.841 | C7: =(RawData!$H$30+RawData!$H$31)/RawData!$B$3+(RawData!$C$60+RawData!$D$60+RawData!$E$60)+(RawData!$H$69+RawData!$H$70)*1/RawData!$B$5 -> 822.57797 | D7: =RawData!$H$32+RawData!$H$33+(RawData!$C$60+RawData!$D$60+RawData!$E$60)+(RawData!$H$69+RawData!$H$70)*1/RawData!$B$5 -> 836.05 | E7: =RawData!$H$34+RawData!$H$35+(RawData!$C$63+RawData!$D$63+RawData!$E$63)+(RawData!$H$69+RawData!$H$70)*1/RawData!$B$5 -> 331.05 | F7: =(RawData!$H$30+RawData!$H$31+(RawData!$C$57+RawData!$D$57+RawData!$E$57))/RawData!$B$4+(RawData!$H$69+RawData!$H$70)*1/RawData!$B$5 -> 6459.9105 | G7: =(RawData!$H$30+RawData!$H$31)/RawData!$B$4+(RawData!$C$60+RawData!$D$60+RawData!$E$60)+(RawData!$H$69+RawData!$H$70)*1/RawData!$B$5 -> 1426.7206 | H7: =RawData!$H$32+RawData!$H$33+(RawData!$C$60+RawData!$D$60+RawData!$E$60)+(RawData!$H$69+RawData!$H$70)*1/RawData!$B$5 -> 836.05 | I7: =RawData!$H$34+RawData!$H$35+(RawData!$C$63+RawData!$D$63+RawData!$E$63)+(RawData!$H$69+RawData!$H$70)*1/RawData!$B$5 -> 331.05 | J7: =B7/B7 -> 1 | K7: =B7/C7 -> 2.6208348 | L7: =B7/D7 -> 2.5786029 | M7: =B7/E7 -> 6.512131 | N7: =F7/F7 -> 1 | O7: =F7/G7 -> 4.5278034 | P7: =F7/H7 -> 7.7267036 | Q7: =F7/I7 -> 19.513398
A8: s8192 | B8: =(RawData!$I$30+RawData!$I$31+(RawData!$C$57+RawData!$D$57+RawData!$E$57))/RawData!$B$3+(RawData!$I$69+RawData!$I$70)*1/RawData!$B$5 -> 2482.6638 | C8: =(RawData!$I$30+RawData!$I$31)/RawData!$B$3+(RawData!$C$60+RawData!$D$60+RawData!$E$60)+(RawData!$I$69+RawData!$I$70)*1/RawData!$B$5 -> 1149.4008 | D8: =RawData!$I$32+RawData!$I$33+(RawData!$C$60+RawData!$D$60+RawData!$E$60)+(RawData!$I$69+RawData!$I$70)*1/RawData!$B$5 -> 1034.55 | E8: =RawData!$I$34+RawData!$I$35+(RawData!$C$63+RawData!$D$63+RawData!$E$63)+(RawData!$I$69+RawData!$I$70)*1/RawData!$B$5 -> 416.55 | F8: =(RawData!$I$30+RawData!$I$31+(RawData!$C$57+RawData!$D$57+RawData!$E$57))/RawData!$B$4+(RawData!$I$69+RawData!$I$70)*1/RawData!$B$5 -> 7412.7221 | G8: =(RawData!$I$30+RawData!$I$31)/RawData!$B$4+(RawData!$C$60+RawData!$D$60+RawData!$E$60)+(RawData!$I$69+RawData!$I$70)*1/RawData!$B$5 -> 2379.5322 | H8: =RawData!$I$32+RawData!$I$33+(RawData!$C$60+RawData!$D$60+RawData!$E$60)+(RawData!$I$69+RawData!$I$70)*1/RawData!$B$5 -> 1034.55 | I8: =RawData!$I$34+RawData!$I$35+(RawData!$C$63+RawData!$D$63+RawData!$E$63)+(RawData!$I$69+RawData!$I$70)*1/RawData!$B$5 -> 416.55 | J8: =B8/B8 -> 1 | K8: =B8/C8 -> 2.1599635 | L8: =B8/D8 -> 2.3997524 | M8: =B8/E8 -> 5.960062 | N8: =F8/F8 -> 1 | O8: =F8/G8 -> 3.1152014 | P8: =F8/H8 -> 7.1651656 | Q8: =F8/I8 -> 17.795516
A9: s16384 | B9: =(RawData!$J$30+RawData!$J$31+(RawData!$C$57+RawData!$D$57+RawData!$E$57))/RawData!$B$3+(RawData!$J$69+RawData!$J$70)*1/RawData!$B$5 -> 3080.1761 | C9: =(RawData!$J$30+RawData!$J$31)/RawData!$B$3+(RawData!$C$60+RawData!$D$60+RawData!$E$60)+(RawData!$J$69+RawData!$J$70)*1/RawData!$B$5 -> 1746.9131 | D9: =RawData!$J$32+RawData!$J$33+(RawData!$C$60+RawData!$D$60+RawData!$E$60)+(RawData!$J$69+RawData!$J$70)*1/RawData!$B$5 -> 1474.55 | E9: =RawData!$J$34+RawData!$J$35+(RawData!$C$63+RawData!$D$63+RawData!$E$63)+(RawData!$J$69+RawData!$J$70)*1/RawData!$B$5 -> 484.55 | F9: =(RawData!$J$30+RawData!$J$31+(RawData!$C$57+RawData!$D$57+RawData!$E$57))/RawData!$B$4+(RawData!$J$69+RawData!$J$70)*1/RawData!$B$5 -> 9148.6123 | G9: =(RawData!$J$30+RawData!$J$31)/RawData!$B$4+(RawData!$C$60+RawData!$D$60+RawData!$E$60)+(RawData!$J$69+RawData!$J$70)*1/RawData!$B$5 -> 4115.4224 | H9: =RawData!$J$32+RawData!$J$33+(RawData!$C$60+RawData!$D$60+RawData!$E$60)+(RawData!$J$69+RawData!$J$70)*1/RawData!$B$5 -> 1474.55 | I9: =RawData!$J$34+RawData!$J$35+(RawData!$C$63+RawData!$D$63+RawData!$E$63)+(RawData!$J$69+RawData!$J$70)*1/RawData!$B$5 -> 484.55 | J9: =B9/B9 -> 1 | K9: =B9/C9 -> 1.7632108 | L9: =B9/D9 -> 2.0888923 | M9: =B9/E9 -> 6.3567766 | N9: =F9/F9 -> 1 | O9: =F9/G9 -> 2.2230069 | P9: =F9/H9 -> 6.2043419 | Q9: =F9/I9 -> 18.880636

Sheet Decode_BS8
A1: Decode BS=8 — totals and speedup vs C1 (formulas)
A3: seq | B3: C1 (ISO-AREA) | C3: C2 (ISO-AREA) | D3: C3 (ISO-AREA) | E3: C4 (ISO-AREA) | F3: C1 (ISO-POWER) | G3: C2 (ISO-POWER) | H3: C3 (ISO-POWER) | I3: C4 (ISO-POWER) | J3: C1 speedup (IA) | K3: C2 speedup (IA) | L3: C3 speedup (IA) | M3: C4 speedup (IA) | N3: C1 speedup (IP) | O3: C2 speedup (IP) | P3: C3 speedup (IP) | Q3: C4 speedup (IP)
A4: s512 | B4: =(RawData!$E$39+RawData!$E$40+(RawData!$C$58+RawData!$D$58+RawData!$E$58))/RawData!$B$3+(RawData!$E$69+RawData!$E$70)*8/RawData!$B$5 -> 2313.503 | C4: =(RawData!$E$39+RawData!$E$40)/RawData!$B$3+(RawData!$C$61+RawData!$D$61+RawData!$E$61)+(RawData!$E$69+RawData!$E$70)*8/RawData!$B$5 -> 980.24004 | D4: =RawData!$E$41+RawData!$E$42+(RawData!$C$61+RawData!$D$61+RawData!$E$61)+(RawData!$E$69+RawData!$E$70)*8/RawData!$B$5 -> 1539.4 | E4: =RawData!$E$43+RawData!$E$44+(RawData!$C$64+RawData!$D$64+RawData!$E$64)+(RawData!$E$69+RawData!$E$70)*8/RawData!$B$5 -> 1261.27 | F4: =(RawData!$E$39+RawData!$E$40+(RawData!$C$58+RawData!$D$58+RawData!$E$58))/RawData!$B$4+(RawData!$E$69+RawData!$E$70)*8/RawData!$B$5 -> 6776.0558 | G4: =(RawData!$E$39+RawData!$E$40)/RawData!$B$4+(RawData!$C$61+RawData!$D$61+RawData!$E$61)+(RawData!$E$69+RawData!$E$70)*8/RawData!$B$5 -> 1742.8659 | H4: =RawData!$E$41+RawData!$E$42+(RawData!$C$61+RawData!$D$61+RawData!$E$61)+(RawData!$E$69+RawData!$E$70)*8/RawData!$B$5 -> 1539.4 | I4: =RawData!$E$43+RawData!$E$44+(RawData!$C$64+RawData!$D$64+RawData!$E$64)+(RawData!$E$69+RawData!$E$70)*8/RawData!$B$5 -> 1261.27 | J4: =B4/B4 -> 1 | K4: =B4/C4 -> 2.3601393 | L4: =B4/D4 -> 1.5028602 | M4: =B4/E4 -> 1.8342647 | N4: =F4/F4 -> 1 | O4: =F4/G4 -> 3.8878814 | P4: =F4/H4 -> 4.4017512 | Q4: =F4/I4 -> 5.372407
A5: s1024 | B5: =(RawData!$F$39+RawData!$F$40+(RawData!$C$58+RawData!$D$58+RawData!$E$58))/RawData!$B$3+(RawData!$F$69+RawData!$F$70)*8/RawData!$B$5 -> 2621.5541 | C5: =(RawData!$F$39+RawData!$F$40)/RawData!$B$3+(RawData!$C$61+RawData!$D$61+RawData!$E$61)+(RawData!$F$69+RawData!$F$70)*8/RawData!$B$5 -> 1288.2911 | D5: =RawData!$F$41+RawData!$F$42+(RawData!$C$61+RawData!$D$61+RawData!$E$61)+(RawData!$F$69+RawData!$F$70)*8/RawData!$B$5 -> 1555.4 | E5: =RawData!$F$43+RawData!$F$44+(RawData!$C$64+RawData!$D$64+RawData!$E$64)+(RawData!$F$69+RawData!$F$70)*8/RawData!$B$5 -> 1266.27 | F5: =(RawData!$F$39+RawData!$F$40+(RawData!$C$58+RawData!$D$58+RawData!$E$58))/RawData!$B$4+(RawData!$F$69+RawData!$F$70)*8/RawData!$B$5 -> 7675.1418 | G5: =(RawData!$F$39+RawData!$F$40)/RawData!$B$4+(RawData!$C$61+RawData!$D$61+RawData!$E$61)+(RawData!$F$69+RawData!$F$70)*8/RawData!$B$5 -> 2641.9519 | H5: =RawData!$F$41+RawData!$F$42+(RawData!$C$61+RawData!$D$61+RawData!$E$61)+(RawData!$F$69+RawData!$F$70)*8/RawData!$B$5 -> 1555.4 | I5: =RawData!$F$43+RawData!$F$44+(RawData!$C$64+RawData!$D$64+RawData!$E$64)+(RawData!$F$69+RawData!$F$70)*8/RawData!$B$5 -> 1266.27 | J5: =B5/B5 -> 1 | K5: =B5/C5 -> 2.0349082 | L5: =B5/D5 -> 1.6854533 | M5: =B5/E5 -> 2.0702963 | N5: =F5/F5 -> 1 | O5: =F5/G5 -> 2.9051028 | P5: =F5/H5 -> 4.9345132 | Q5: =F5/I5 -> 6.0612206
A6: s2048 | B6: =(RawData!$G$39+RawData!$G$40+(RawData!$C$58+RawData!$D$58+RawData!$E$58))/RawData!$B$3+(RawData!$G$69+RawData!$G$70)*8/RawData!$B$5 -> 3220.8887 | C6: =(RawData!$G$39+RawData!$G$40)/RawData!$B$3+(RawData!$C$61+RawData!$D$61+RawData!$E$61)+(RawData!$G$69+RawData!$G$70)*8/RawData!$B$5 -> 1887.6257 | D6: =RawData!$G$41+RawData!$G$42+(RawData!$C$61+RawData!$D$61+RawData!$E$61)+(RawData!$G$69+RawData!$G$70)*8/RawData!$B$5 -> 2129.4 | E6: =RawData!$G$43+RawData!$G$44+(RawData!$C$64+RawData!$D$64+RawData!$E$64)+(RawData!$G$69+RawData!$G$70)*8/RawData!$B$5 -> 1317.27 | F6: =(RawData!$G$39+RawData!$G$40+(RawData!$C$58+RawData!$D$58+RawData!$E$58))/RawData!$B$4+(RawData!$G$69+RawData!$G$70)*8/RawData!$B$5 -> 9410.4712 | G6: =(RawData!$G$39+RawData!$G$40)/RawData!$B$4+(RawData!$C$61+RawData!$D$61+RawData!$E$61)+(RawData!$G$69+RawData!$G$70)*8/RawData!$B$5 -> 4377.2813 | H6: =RawData!$G$41+RawData!$G$42+(RawData!$C$61+RawData!$D$61+RawData!$E$61)+(RawData!$G$69+RawData!$G$70)*8/RawData!$B$5 -> 2129.4 | I6: =RawData!$G$43+RawData!$G$44+(RawData!$C$64+RawData!$D$64+RawData!$E$64)+(RawData!$G$69+RawData!$G$70)*8/RawData!$B$5 -> 1317.27 | J6: =B6/B6 -> 1 | K6: =B6/C6 -> 1.7063175 | L6: =B6/D6 -> 1.5125804 | M6: =B6/E6 -> 2.4451242 | N6: =F6/F6 -> 1 | O6: =F6/G6 -> 2.1498438 | P6: =F6/H6 -> 4.4193065 | Q6: =F6/I6 -> 7.1439198
A7: s4096 | B7: =(RawData!$H$39+RawData!$H$40+(RawData!$C$58+RawData!$D$58+RawData!$E$58))/RawData!$B$3+(RawData!$H$69+RawData!$H$70)*8/RawData!$B$5 -> 4448.8868 | C7: =(RawData!$H$39+RawData!$H$40)/RawData!$B$3+(RawData!$C$61+RawData!$D$61+RawData!$E$61)+(RawData!$H$69+RawData!$H$70)*8/RawData!$B$5 -> 3115.6237 | D7: =RawData!$H$41+RawData!$H$42+(RawData!$C$61+RawData!$D$61+RawData!$E$61)+(RawData!$H$69+RawData!$H$70)*8/RawData!$B$5 -> 3223.4 | E7: =RawData!$H$43+RawData!$H$44+(RawData!$C$64+RawData!$D$64+RawData!$E$64)+(RawData!$H$69+RawData!$H$70)*8/RawData!$B$5 -> 1386.27 | F7: =(RawData!$H$39+RawData!$H$40+(RawData!$C$58+RawData!$D$58+RawData!$E$58))/RawData!$B$4+(RawData!$H$69+RawData!$H$70)*8/RawData!$B$5 -> 12981.955 | G7: =(RawData!$H$39+RawData!$H$40)/RawData!$B$4+(RawData!$C$61+RawData!$D$61+RawData!$E$61)+(RawData!$H$69+RawData!$H$70)*8/RawData!$B$5 -> 7948.765 | H7: =RawData!$H$41+RawData!$H$42+(RawData!$C$61+RawData!$D$61+RawData!$E$61)+(RawData!$H$69+RawData!$H$70)*8/RawData!$B$5 -> 3223.4 | I7: =RawData!$H$43+RawData!$H$44+(RawData!$C$64+RawData!$D$64+RawData!$E$64)+(RawData!$H$69+RawData!$H$70)*8/RawData!$B$5 -> 1386.27 | J7: =B7/B7 -> 1 | K7: =B7/C7 -> 1.4279281 | L7: =B7/D7 -> 1.3801845 | M7: =B7/E7 -> 3.2092498 | N7: =F7/F7 -> 1 | O7: =F7/G7 -> 1.633204 | P7: =F7/H7 -> 4.0274105 | Q7: =F7/I7 -> 9.3646655
A8: s8192 | B8: =(RawData!$I$39+RawData!$I$40+(RawData!$C$58+RawData!$D$58+RawData!$E$58))/RawData!$B$3+(RawData!$I$69+RawData!$I$70)*8/RawData!$B$5 -> 7063.4697 | C8: =(RawData!$I$39+RawData!$I$40)/RawData!$B$3+(RawData!$C$61+RawData!$D$61+RawData!$E$61)+(RawData!$I$69+RawData!$I$70)*8/RawData!$B$5 -> 5730.2067 | D8: =RawData!$I$41+RawData!$I$42+(RawData!$C$61+RawData!$D$61+RawData!$E$61)+(RawData!$I$69+RawData!$I$70)*8/RawData!$B$5 -> 4811.4 | E8: =RawData!$I$43+RawData!$I$44+(RawData!$C$64+RawData!$D$64+RawData!$E$64)+(RawData!$I$69+RawData!$I$70)*8/RawData!$B$5 -> 2075.27 | F8: =(RawData!$I$39+RawData!$I$40+(RawData!$C$58+RawData!$D$58+RawData!$E$58))/RawData!$B$4+(RawData!$I$69+RawData!$I$70)*8/RawData!$B$5 -> 20604.447 | G8: =(RawData!$I$39+RawData!$I$40)/RawData!$B$4+(RawData!$C$61+RawData!$D$61+RawData!$E$61)+(RawData!$I$69+RawData!$I$70)*8/RawData!$B$5 -> 15571.258 | H8: =RawData!$I$41+RawData!$I$42+(RawData!$C$61+RawData!$D$61+RawData!$E$61)+(RawData!$I$69+RawData!$I$70)*8/RawData!$B$5 -> 4811.4 | I8: =RawData!$I$43+RawData!$I$44+(RawData!$C$64+RawData!$D$64+RawData!$E$64)+(RawData!$I$69+RawData!$I$70)*8/RawData!$B$5 -> 2075.27 | J8: =B8/B8 -> 1 | K8: =B8/C8 -> 1.2326728 | L8: =B8/D8 -> 1.4680695 | M8: =B8/E8 -> 3.4036389 | N8: =F8/F8 -> 1 | O8: =F8/G8 -> 1.3232359 | P8: =F8/H8 -> 4.2824225 | Q8: =F8/I8 -> 9.9285623
A9: s16384 | B9: =(RawData!$J$39+RawData!$J$40+(RawData!$C$58+RawData!$D$58+RawData!$E$58))/RawData!$B$3+(RawData!$J$69+RawData!$J$70)*8/RawData!$B$5 -> 11843.568 | C9: =(RawData!$J$39+RawData!$J$40)/RawData!$B$3+(RawData!$C$61+RawData!$D$61+RawData!$E$61)+(RawData!$J$69+RawData!$J$70)*8/RawData!$B$5 -> 10510.305 | D9: =RawData!$J$41+RawData!$J$42+(RawData!$C$61+RawData!$D$61+RawData!$E$61)+(RawData!$J$69+RawData!$J$70)*8/RawData!$B$5 -> 8331.4 | E9: =RawData!$J$43+RawData!$J$44+(RawData!$C$64+RawData!$D$64+RawData!$E$64)+(RawData!$J$69+RawData!$J$70)*8/RawData!$B$5 -> 2612.27 | F9: =(RawData!$J$39+RawData!$J$40+(RawData!$C$58+RawData!$D$58+RawData!$E$58))/RawData!$B$4+(RawData!$J$69+RawData!$J$70)*8/RawData!$B$5 -> 34491.569 | G9: =(RawData!$J$39+RawData!$J$40)/RawData!$B$4+(RawData!$C$61+RawData!$D$61+RawData!$E$61)+(RawData!$J$69+RawData!$J$70)*8/RawData!$B$5 -> 29458.379 | H9: =RawData!$J$41+RawData!$J$42+(RawData!$C$61+RawData!$D$61+RawData!$E$61)+(RawData!$J$69+RawData!$J$70)*8/RawData!$B$5 -> 8331.4 | I9: =RawData!$J$43+RawData!$J$44+(RawData!$C$64+RawData!$D$64+RawData!$E$64)+(RawData!$J$69+RawData!$J$70)*8/RawData!$B$5 -> 2612.27 | J9: =B9/B9 -> 1 | K9: =B9/C9 -> 1.1268529 | L9: =B9/D9 -> 1.4215579 | M9: =B9/E9 -> 4.5338222 | N9: =F9/F9 -> 1 | O9: =F9/G9 -> 1.1708577 | P9: =F9/H9 -> 4.1399488 | Q9: =F9/I9 -> 13.203677

Sheet Decode_BS64
A1: Decode BS=64 — totals and speedup vs C1 (formulas)
A3: seq | B3: C1 (ISO-AREA) | C3: C2 (ISO-AREA) | D3: C3 (ISO-AREA) | E3: C4 (ISO-AREA) | F3: C1 (ISO-POWER) | G3: C2 (ISO-POWER) | H3: C3 (ISO-POWER) | I3: C4 (ISO-POWER) | J3: C1 speedup (IA) | K3: C2 speedup (IA) | L3: C3 speedup (IA) | M3: C4 speedup (IA) | N3: C1 speedup (IP) | O3: C2 speedup (IP) | P3: C3 speedup (IP) | Q3: C4 speedup (IP)
A4: s512 | B4: =(RawData!$E$48+RawData!$E$49+(RawData!$C$59+RawData!$D$59+RawData!$E$59))/RawData!$B$3+(RawData!$E$69+RawData!$E$70)*64/RawData!$B$5 -> 18508.024 | C4: =(RawData!$E$48+RawData!$E$49)/RawData!$B$3+(RawData!$C$62+RawData!$D$62+RawData!$E$62)+(RawData!$E$69+RawData!$E$70)*64/RawData!$B$5 -> 4871.9203 | D4: =RawData!$E$50+RawData!$E$51+(RawData!$C$62+RawData!$D$62+RawData!$E$62)+(RawData!$E$69+RawData!$E$70)*64/RawData!$B$5 -> 9345.2 | E4: =RawData!$E$52+RawData!$E$53+(RawData!$C$65+RawData!$D$65+RawData!$E$65)+(RawData!$E$69+RawData!$E$70)*64/RawData!$B$5 -> 8826.2 | F4: =(RawData!$E$48+RawData!$E$49+(RawData!$C$59+RawData!$D$59+RawData!$E$59))/RawData!$B$4+(RawData!$E$69+RawData!$E$70)*64/RawData!$B$5 -> 54208.446 | G4: =(RawData!$E$48+RawData!$E$49)/RawData!$B$4+(RawData!$C$62+RawData!$D$62+RawData!$E$62)+(RawData!$E$69+RawData!$E$70)*64/RawData!$B$5 -> 10972.927 | H4: =RawData!$E$50+RawData!$E$51+(RawData!$C$62+RawData!$D$62+RawData!$E$62)+(RawData!$E$69+RawData!$E$70)*64/RawData!$B$5 -> 9345.2 | I4: =RawData!$E$52+RawData!$E$53+(RawData!$C$65+RawData!$D$65+RawData!$E$65)+(RawData!$E$69+RawData!$E$70)*64/RawData!$B$5 -> 8826.2 | J4: =B4/B4 -> 1 | K4: =B4/C4 -> 3.7989177 | L4: =B4/D4 -> 1.9804846 | M4: =B4/E4 -> 2.0969414 | N4: =F4/F4 -> 1 | O4: =F4/G4 -> 4.9401993 | P4: =F4/H4 -> 5.8006727 | Q4: =F4/I4 -> 6.141765
A5: s1024 | B5: =(RawData!$F$48+RawData!$F$49+(RawData!$C$59+RawData!$D$59+RawData!$E$59))/RawData!$B$3+(RawData!$F$69+RawData!$F$70)*64/RawData!$B$5 -> 20972.433 | C5: =(RawData!$F$48+RawData!$F$49)/RawData!$B$3+(RawData!$C$62+RawData!$D$62+RawData!$E$62)+(RawData!$F$69+RawData!$F$70)*64/RawData!$B$5 -> 7336.3286 | D5: =RawData!$F$50+RawData!$F$51+(RawData!$C$62+RawData!$D$62+RawData!$E$62)+(RawData!$F$69+RawData!$F$70)*64/RawData!$B$5 -> 9473.2 | E5: =RawData!$F$52+RawData!$F$53+(RawData!$C$65+RawData!$D$65+RawData!$E$65)+(RawData!$F$69+RawData!$F$70)*64/RawData!$B$5 -> 8866.2 | F5: =(RawData!$F$48+RawData!$F$49+(RawData!$C$59+RawData!$D$59+RawData!$E$59))/RawData!$B$4+(RawData!$F$69+RawData!$F$70)*64/RawData!$B$5 -> 61401.135 | G5: =(RawData!$F$48+RawData!$F$49)/RawData!$B$4+(RawData!$C$62+RawData!$D$62+RawData!$E$62)+(RawData!$F$69+RawData!$F$70)*64/RawData!$B$5 -> 18165.615 | H5: =RawData!$F$50+RawData!$F$51+(RawData!$C$62+RawData!$D$62+RawData!$E$62)+(RawData!$F$69+RawData!$F$70)*64/RawData!$B$5 -> 9473.2 | I5: =RawData!$F$52+RawData!$F$53+(RawData!$C$65+RawData!$D$65+RawData!$E$65)+(RawData!$F$69+RawData!$F$70)*64/RawData!$B$5 -> 8866.2 | J5: =B5/B5 -> 1 | K5: =B5/C5 -> 2.8587096 | L5: =B5/D5 -> 2.2138699 | M5: =B5/E5 -> 2.3654364 | N5: =F5/F5 -> 1 | O5: =F5/G5 -> 3.3800746 | P5: =F5/H5 -> 6.4815622 | Q5: =F5/I5 -> 6.9253045
A6: s2048 | B6: =(RawData!$G$48+RawData!$G$49+(RawData!$C$59+RawData!$D$59+RawData!$E$59))/RawData!$B$3+(RawData!$G$69+RawData!$G$70)*64/RawData!$B$5 -> 25767.11 | C6: =(RawData!$G$48+RawData!$G$49)/RawData!$B$3+(RawData!$C$62+RawData!$D$62+RawData!$E$62)+(RawData!$G$69+RawData!$G$70)*64/RawData!$B$5 -> 12131.006 | D6: =RawData!$G$50+RawData!$G$51+(RawData!$C$62+RawData!$D$62+RawData!$E$62)+(RawData!$G$69+RawData!$G$70)*64/RawData!$B$5 -> 14065.2 | E6: =RawData!$G$52+RawData!$G$53+(RawData!$C$65+RawData!$D$65+RawData!$E$65)+(RawData!$G$69+RawData!$G$70)*64/RawData!$B$5 -> 9274.2 | F6: =(RawData!$G$48+RawData!$G$49+(RawData!$C$59+RawData!$D$59+RawData!$E$59))/RawData!$B$4+(RawData!$G$69+RawData!$G$70)*64/RawData!$B$5 -> 75283.77 | G6: =(RawData!$G$48+RawData!$G$49)/RawData!$B$4+(RawData!$C$62+RawData!$D$62+RawData!$E$62)+(RawData!$G$69+RawData!$G$70)*64/RawData!$B$5 -> 32048.25 | H6: =RawData!$G$50+RawData!$G$51+(RawData!$C$62+RawData!$D$62+RawData!$E$62)+(RawData!$G$69+RawData!$G$70)*64/RawData!$B$5 -> 14065.2 | I6: =RawData!$G$52+RawData!$G$53+(RawData!$C$65+RawData!$D$65+RawData!$E$65)+(RawData!$G$69+RawData!$G$70)*64/RawData!$B$5 -> 9274.2 | J6: =B6/B6 -> 1 | K6: =B6/C6 -> 2.1240704 | L6: =B6/D6 -> 1.8319761 | M6: =B6/E6 -> 2.7783647 | N6: =F6/F6 -> 1 | O6: =F6/G6 -> 2.3490758 | P6: =F6/H6 -> 5.3524848 | Q6: =F6/I6 -> 8.1175487
A7: s4096 | B7: =(RawData!$H$48+RawData!$H$49+(RawData!$C$59+RawData!$D$59+RawData!$E$59))/RawData!$B$3+(RawData!$H$69+RawData!$H$70)*64/RawData!$B$5 -> 35591.094 | C7: =(RawData!$H$48+RawData!$H$49)/RawData!$B$3+(RawData!$C$62+RawData!$D$62+RawData!$E$62)+(RawData!$H$69+RawData!$H$70)*64/RawData!$B$5 -> 21954.99 | D7: =RawData!$H$50+RawData!$H$51+(RawData!$C$62+RawData!$D$62+RawData!$E$62)+(RawData!$H$69+RawData!$H$70)*64/RawData!$B$5 -> 22817.2 | E7: =RawData!$H$52+RawData!$H$53+(RawData!$C$65+RawData!$D$65+RawData!$E$65)+(RawData!$H$69+RawData!$H$70)*64/RawData!$B$5 -> 9826.2 | F7: =(RawData!$H$48+RawData!$H$49+(RawData!$C$59+RawData!$D$59+RawData!$E$59))/RawData!$B$4+(RawData!$H$69+RawData!$H$70)*64/RawData!$B$5 -> 103855.64 | G7: =(RawData!$H$48+RawData!$H$49)/RawData!$B$4+(RawData!$C$62+RawData!$D$62+RawData!$E$62)+(RawData!$H$69+RawData!$H$70)*64/RawData!$B$5 -> 60620.12 | H7: =RawData!$H$50+RawData!$H$51+(RawData!$C$62+RawData!$D$62+RawData!$E$62)+(RawData!$H$69+RawData!$H$70)*64/RawData!$B$5 -> 22817.2 | I7: =RawData!$H$52+RawData!$H$53+(RawData!$C$65+RawData!$D$65+RawData!$E$65)+(RawData!$H$69+RawData!$H$70)*64/RawData!$B$5 -> 9826.2 | J7: =B7/B7 -> 1 | K7: =B7/C7 -> 1.6210936 | L7: =B7/D7 -> 1.5598362 | M7: =B7/E7 -> 3.6220608 | N7: =F7/F7 -> 1 | O7: =F7/G7 -> 1.7132206 | P7: =F7/H7 -> 4.5516382 | Q7: =F7/I7 -> 10.569258
A8: s8192 | B8: =(RawData!$I$48+RawData!$I$49+(RawData!$C$59+RawData!$D$59+RawData!$E$59))/RawData!$B$3+(RawData!$I$69+RawData!$I$70)*64/RawData!$B$5 -> 56507.757 | C8: =(RawData!$I$48+RawData!$I$49)/RawData!$B$3+(RawData!$C$62+RawData!$D$62+RawData!$E$62)+(RawData!$I$69+RawData!$I$70)*64/RawData!$B$5 -> 42871.653 | D8: =RawData!$I$50+RawData!$I$51+(RawData!$C$62+RawData!$D$62+RawData!$E$62)+(RawData!$I$69+RawData!$I$70)*64/RawData!$B$5 -> 35521.2 | E8: =RawData!$I$52+RawData!$I$53+(RawData!$C$65+RawData!$D$65+RawData!$E$65)+(RawData!$I$69+RawData!$I$70)*64/RawData!$B$5 -> 15338.2 | F8: =(RawData!$I$48+RawData!$I$49+(RawData!$C$59+RawData!$D$59+RawData!$E$59))/RawData!$B$4+(RawData!$I$69+RawData!$I$70)*64/RawData!$B$5 -> 164835.58 | G8: =(RawData!$I$48+RawData!$I$49)/RawData!$B$4+(RawData!$C$62+RawData!$D$62+RawData!$E$62)+(RawData!$I$69+RawData!$I$70)*64/RawData!$B$5 -> 121600.06 | H8: =RawData!$I$50+RawData!$I$51+(RawData!$C$62+RawData!$D$62+RawData!$E$62)+(RawData!$I$69+RawData!$I$70)*64/RawData!$B$5 -> 35521.2 | I8: =RawData!$I$52+RawData!$I$53+(RawData!$C$65+RawData!$D$65+RawData!$E$65)+(RawData!$I$69+RawData!$I$70)*64/RawData!$B$5 -> 15338.2 | J8: =B8/B8 -> 1 | K8: =B8/C8 -> 1.3180681 | L8: =B8/D8 -> 1.5908178 | M8: =B8/E8 -> 3.6841192 | N8: =F8/F8 -> 1 | O8: =F8/G8 -> 1.3555551 | P8: =F8/H8 -> 4.6404846 | Q8: =F8/I8 -> 10.746736
A9: s16384 | B9: =(RawData!$J$48+RawData!$J$49+(RawData!$C$59+RawData!$D$59+RawData!$E$59))/RawData!$B$3+(RawData!$J$69+RawData!$J$70)*64/RawData!$B$5 -> 94748.542 | C9: =(RawData!$J$48+RawData!$J$49)/RawData!$B$3+(RawData!$C$62+RawData!$D$62+RawData!$E$62)+(RawData!$J$69+RawData!$J$70)*64/RawData!$B$5 -> 81112.438 | D9: =RawData!$J$50+RawData!$J$51+(RawData!$C$62+RawData!$D$62+RawData!$E$62)+(RawData!$J$69+RawData!$J$70)*64/RawData!$B$5 -> 63681.2 | E9: =RawData!$J$52+RawData!$J$53+(RawData!$C$65+RawData!$D$65+RawData!$E$65)+(RawData!$J$69+RawData!$J$70)*64/RawData!$B$5 -> 19634.2 | F9: =(RawData!$J$48+RawData!$J$49+(RawData!$C$59+RawData!$D$59+RawData!$E$59))/RawData!$B$4+(RawData!$J$69+RawData!$J$70)*64/RawData!$B$5 -> 275932.55 | G9: =(RawData!$J$48+RawData!$J$49)/RawData!$B$4+(RawData!$C$62+RawData!$D$62+RawData!$E$62)+(RawData!$J$69+RawData!$J$70)*64/RawData!$B$5 -> 232697.03 | H9: =RawData!$J$50+RawData!$J$51+(RawData!$C$62+RawData!$D$62+RawData!$E$62)+(RawData!$J$69+RawData!$J$70)*64/RawData!$B$5 -> 63681.2 | I9: =RawData!$J$52+RawData!$J$53+(RawData!$C$65+RawData!$D$65+RawData!$E$65)+(RawData!$J$69+RawData!$J$70)*64/RawData!$B$5 -> 19634.2 | J9: =B9/B9 -> 1 | K9: =B9/C9 -> 1.1681136 | L9: =B9/D9 -> 1.4878574 | M9: =B9/E9 -> 4.825689 | N9: =F9/F9 -> 1 | O9: =F9/G9 -> 1.1858018 | P9: =F9/H9 -> 4.33303 | Q9: =F9/I9 -> 14.053669
